{
    "registryname": "aquatic_aether_processor",
    "localizedname": "Aquatic Aether Focusing Structure",
    "requires-blueprint": false,
    "color": "4ed8d8",
    "parts": [
        {
            "x": -1,
            "y": 0,
            "z": 1,
            "elements": [
                "glacidus:crystal_block@0"
            ]
        },
        {
            "x": -2,
            "y": 0,
            "z": 2,
            "elements": [
                "modulardiversity:blockbiomedetector@0"
            ]
        },
        {
            "x": 0,
            "y": 0,
            "z": 1,
            "elements": [
                "quark:elder_prismarine_stairs@3"
            ]
        },
        {
            "x": -1,
            "y": 0,
            "z": 2,
            "elements": [
                "quark:elder_prismarine_stairs@1"
            ]
        },
        {
            "x": 1,
            "y": 0,
            "z": 1,
            "elements": [
                "glacidus:crystal_block@0"
            ]
        },
        {
            "x": 0,
            "y": 2,
            "z": -1,
            "elements": [
                "minecraft:prismarine@1"
            ]
        },
        {
            "x": -1,
            "y": 0,
            "z": 3,
            "elements": [
                "glacidus:crystal_block@0"
            ]
        },
        {
            "x": 3,
            "y": 2,
            "z": 2,
            "elements": [
                "minecraft:prismarine@1"
            ]
        },
        {
            "x": 1,
            "y": 0,
            "z": 2,
            "elements": [
                "quark:elder_prismarine_stairs@0"
            ]
        },
        {
            "x": 0,
            "y": 0,
            "z": 3,
            "elements": [
                "quark:elder_prismarine_stairs@2"
            ]
        },
        {
            "x": 0,
            "y": 2,
            "z": 5,
            "elements": [
                "minecraft:prismarine@1"
            ]
        },
        {
            "x": 2,
            "y": 0,
            "z": 2,
            "elements": [
                "modularmachinery:blockfluidinputhatch@3"
            ]
        },
        {
            "x": 1,
            "y": 0,
            "z": 3,
            "elements": [
                "glacidus:crystal_block@0"
            ]
        },
        {
            "x": 0,
            "y": 0,
            "z": 4,
            "elements": [
                "modularmachinery:blockinputbus@2"
            ]
        },
        {
            "x": 1,
            "y": -1,
            "z": 0,
            "elements": [
                "quark:prismarine_stairs@2"
            ]
        },
        {
            "x": 0,
            "y": -1,
            "z": 0,
            "elements": [
                "modulardiversity:blockweatherdetector"
            ]
        },
        {
            "x": -3,
            "y": 1,
            "z": 2,
            "elements": [
                "quark:prismarine_stairs@4"
            ]
        },
        {
            "x": -1,
            "y": -1,
            "z": 0,
            "elements": [
                "quark:prismarine_stairs@2"
            ]
        },
        {
            "x": -1,
            "y": 1,
            "z": 1,
            "elements": [
                "glacidus:small_crystal@5"
            ]
        },
        {
            "x": 0,
            "y": 1,
            "z": 0,
            "elements": [
                "quark:prismarine_stairs@3"
            ]
        },
        {
            "x": -2,
            "y": 1,
            "z": 2,
            "elements": [
                "quark:prismarine_stairs@1"
            ]
        },
        {
            "x": -2,
            "y": -1,
            "z": 1,
            "elements": [
                "quark:prismarine_stairs@0"
            ]
        },
        {
            "x": 1,
            "y": 1,
            "z": 1,
            "elements": [
                "glacidus:small_crystal@5"
            ]
        },
        {
            "x": 0,
            "y": 1,
            "z": -1,
            "elements": [
                "quark:prismarine_stairs@6"
            ]
        },
        {
            "x": -1,
            "y": 1,
            "z": 3,
            "elements": [
                "glacidus:small_crystal@5"
            ]
        },
        {
            "x": -2,
            "y": -1,
            "z": 2,
            "elements": [
                "minecraft:prismarine@1"
            ]
        },
        {
            "x": 3,
            "y": 3,
            "z": 2,
            "elements": [
                "glacidus:small_crystal@5"
            ]
        },
        {
            "x": -2,
            "y": -1,
            "z": 3,
            "elements": [
                "quark:prismarine_stairs@0"
            ]
        },
        {
            "x": 0,
            "y": 3,
            "z": 5,
            "elements": [
                "glacidus:small_crystal@5"
            ]
        },
        {
            "x": -1,
            "y": -1,
            "z": 2,
            "elements": [
                "quark:elder_prismarine@2"
            ]
        },
        {
            "x": 0,
            "y": -1,
            "z": 1,
            "elements": [
                "quark:elder_prismarine@2"
            ]
        },
        {
            "x": 0,
            "y": 3,
            "z": -1,
            "elements": [
                "glacidus:small_crystal@5"
            ]
        },
        {
            "x": 2,
            "y": 1,
            "z": 2,
            "elements": [
                "quark:prismarine_stairs@0"
            ]
        },
        {
            "x": 1,
            "y": 1,
            "z": 3,
            "elements": [
                "glacidus:small_crystal@5"
            ]
        },
        {
            "x": 0,
            "y": 1,
            "z": 4,
            "elements": [
                "quark:prismarine_stairs@2"
            ]
        },
        {
            "x": 0,
            "y": -1,
            "z": 2,
            "elements": [
                "modularmachinery:blockoutputbus@2"
            ]
        },
        {
            "x": 2,
            "y": -1,
            "z": 1,
            "elements": [
                "quark:prismarine_stairs@1"
            ]
        },
        {
            "x": 3,
            "y": 1,
            "z": 2,
            "elements": [
                "quark:prismarine_stairs@5"
            ]
        },
        {
            "x": -1,
            "y": -1,
            "z": 4,
            "elements": [
                "quark:prismarine_stairs@3"
            ]
        },
        {
            "x": 0,
            "y": 1,
            "z": 5,
            "elements": [
                "quark:prismarine_stairs@7"
            ]
        },
        {
            "x": 0,
            "y": -1,
            "z": 3,
            "elements": [
                "quark:elder_prismarine@2"
            ]
        },
        {
            "x": 1,
            "y": -1,
            "z": 2,
            "elements": [
                "quark:elder_prismarine@2"
            ]
        },
        {
            "x": 2,
            "y": -1,
            "z": 2,
            "elements": [
                "minecraft:prismarine@1"
            ]
        },
        {
            "x": 0,
            "y": -1,
            "z": 4,
            "elements": [
                "minecraft:prismarine@1"
            ]
        },
        {
            "x": 1,
            "y": -1,
            "z": 4,
            "elements": [
                "quark:prismarine_stairs@3"
            ]
        },
        {
            "x": 2,
            "y": -1,
            "z": 3,
            "elements": [
                "quark:prismarine_stairs@1"
            ]
        },
        {
            "x": -3,
            "y": 2,
            "z": 2,
            "elements": [
                "minecraft:prismarine@1"
            ]
        }
    ]}