{
    "registryname": "gaia_maker",
    "localizedname": "Gaia Spirit Synthesizer",
    "requires-blueprint": false,
    "color": "F2F2F2",
    "parts": [
        {
            "x": -3,
            "y": -4,
            "z": -2,
            "elements": [
                "astralsorcery:blockmarble@2"
            ]
        },
        {
            "x": -1,
            "y": 0,
            "z": 0,
            "elements": [
                "astralsorcery:blockmarble@1"
            ]
        },
        {
            "x": 1,
            "y": 2,
            "z": 1,
            "elements": [
                "astralsorcery:blockmarble@1"
            ]
        },
        {
            "x": -3,
            "y": 0,
            "z": 4,
            "elements": [
                "astralsorcery:blockmarble@5"
            ]
        },
        {
            "x": 1,
            "y": 0,
            "z": 0,
            "elements": [
                "astralsorcery:blockmarble@1"
            ]
        },
        {
            "x": -3,
            "y": -6,
            "z": 1,
            "elements": [
                "astralsorcery:blockmarble@1"
            ]
        },
        {
            "x": 3,
            "y": 0,
            "z": 4,
            "elements": [
                "astralsorcery:blockmarble@5"
            ]
        },
        {
            "x": 3,
            "y": -6,
            "z": 1,
            "elements": [
                "astralsorcery:blockmarble@1"
            ]
        },
        {
            "x": 3,
            "y": -5,
            "z": -2,
            "elements": [
                "astralsorcery:blockmarble@2"
            ]
        },
        {
            "x": 1,
            "y": -1,
            "z": 0,
            "elements": [
                "astralsorcery:blockmarble@6"
            ]
        },
        {
            "x": 0,
            "y": -1,
            "z": 0,
            "elements": [
                "astralsorcery:blockmarble@2"
            ]
        },
        {
            "x": -1,
            "y": 1,
            "z": 0,
            "elements": [
                "astralsorcery:blockmarble@5"
            ]
        },
        {
            "x": 0,
            "y": 1,
            "z": 0,
            "elements": [
                "astralsorcery:blockmarble@2"
            ]
        },
        {
            "x": -3,
            "y": -5,
            "z": -2,
            "elements": [
                "astralsorcery:blockmarble@2"
            ]
        },
        {
            "x": -1,
            "y": -1,
            "z": 0,
            "elements": [
                "astralsorcery:blockmarble@6"
            ]
        },
        {
            "x": -3,
            "y": 1,
            "z": 4,
            "elements": [
                "astralsorcery:blockmarbleslab@0"
            ]
        },
        {
            "x": 1,
            "y": 1,
            "z": 0,
            "elements": [
                "astralsorcery:blockmarble@5"
            ]
        },
        {
            "x": -2,
            "y": 1,
            "z": 4,
            "elements": [
                "astralsorcery:blockmarbleslab@0"
            ]
        },
        {
            "x": 0,
            "y": -3,
            "z": 2,
            "elements": [
                "astralsorcery:blockmarble@2"
            ]
        },
        {
            "x": 2,
            "y": 1,
            "z": 4,
            "elements": [
                "astralsorcery:blockmarbleslab@0"
            ]
        },
        {
            "x": 3,
            "y": 1,
            "z": 4,
            "elements": [
                "astralsorcery:blockmarbleslab@0"
            ]
        },
        {
            "x": 3,
            "y": -6,
            "z": -2,
            "elements": [
                "astralsorcery:blockmarble@6"
            ]
        },
        {
            "x": 2,
            "y": -6,
            "z": -2,
            "elements": [
                "astralsorcery:blockmarble@1"
            ]
        },
        {
            "x": 1,
            "y": -6,
            "z": -2,
            "elements": [
                "astralsorcery:blockmarble@1"
            ]
        },
        {
            "x": 0,
            "y": -6,
            "z": -2,
            "elements": [
                "astralsorcery:blockmarble@1"
            ]
        },
        {
            "x": -2,
            "y": 2,
            "z": 0,
            "elements": [
                "astralsorcery:blockmarbleslab@0"
            ]
        },
        {
            "x": -1,
            "y": -6,
            "z": -2,
            "elements": [
                "astralsorcery:blockmarble@1"
            ]
        },
        {
            "x": -2,
            "y": -6,
            "z": -2,
            "elements": [
                "astralsorcery:blockmarble@1"
            ]
        },
        {
            "x": 0,
            "y": -2,
            "z": 0,
            "elements": [
                "astralsorcery:blockmarble@2"
            ]
        },
        {
            "x": -1,
            "y": 2,
            "z": 0,
            "elements": [
                "astralsorcery:blockmarbleslab@0"
            ]
        },
        {
            "x": 0,
            "y": 2,
            "z": 0,
            "elements": [
                "astralsorcery:blockmarble@1"
            ]
        },
        {
            "x": -3,
            "y": -6,
            "z": -2,
            "elements": [
                "astralsorcery:blockmarble@6"
            ]
        },
        {
            "x": 1,
            "y": 2,
            "z": 0,
            "elements": [
                "astralsorcery:blockmarbleslab@0"
            ]
        },
        {
            "x": 2,
            "y": 2,
            "z": 0,
            "elements": [
                "astralsorcery:blockmarbleslab@0"
            ]
        },
        {
            "x": 0,
            "y": -2,
            "z": 2,
            "elements": [
                "astralsorcery:blockmarble@2"
            ]
        },
        {
            "x": 0,
            "y": -4,
            "z": 1,
            "elements": [
                "modularmachinery:blockoutputbus@0"
            ]
        },
        {
            "x": -3,
            "y": -6,
            "z": 4,
            "elements": [
                "astralsorcery:blockmarble@6"
            ]
        },
        {
            "x": -2,
            "y": -6,
            "z": 4,
            "elements": [
                "astralsorcery:blockmarble@1"
            ]
        },
        {
            "x": -1,
            "y": -6,
            "z": 4,
            "elements": [
                "astralsorcery:blockmarble@1"
            ]
        },
        {
            "x": 0,
            "y": -6,
            "z": 4,
            "elements": [
                "astralsorcery:blockmarble@1"
            ]
        },
        {
            "x": 1,
            "y": -6,
            "z": 4,
            "elements": [
                "astralsorcery:blockmarble@1"
            ]
        },
        {
            "x": 2,
            "y": -6,
            "z": 4,
            "elements": [
                "astralsorcery:blockmarble@1"
            ]
        },
        {
            "x": 3,
            "y": -6,
            "z": 4,
            "elements": [
                "astralsorcery:blockmarble@6"
            ]
        },
        {
            "x": 0,
            "y": -3,
            "z": 0,
            "elements": [
                "astralsorcery:blockmarble@2"
            ]
        },
        {
            "x": -3,
            "y": 1,
            "z": 3,
            "elements": [
                "astralsorcery:blockmarbleslab@0"
            ]
        },
        {
            "x": 3,
            "y": 1,
            "z": -2,
            "elements": [
                "astralsorcery:blockmarbleslab@0"
            ]
        },
        {
            "x": -2,
            "y": 1,
            "z": 3,
            "elements": [
                "astralsorcery:blockmarble@5"
            ]
        },
        {
            "x": 2,
            "y": 1,
            "z": -2,
            "elements": [
                "astralsorcery:blockmarbleslab@0"
            ]
        },
        {
            "x": -3,
            "y": -3,
            "z": 1,
            "elements": [
                "botania:pylon@2"
            ]
        },
        {
            "x": -1,
            "y": -1,
            "z": 2,
            "elements": [
                "astralsorcery:blockmarble@6"
            ]
        },
        {
            "x": -1,
            "y": -3,
            "z": 1,
            "elements": [
                "astralsorcery:blockmarble@2"
            ]
        },
        {
            "x": 0,
            "y": -1,
            "z": 2,
            "elements": [
                "astralsorcery:blockmarble@2"
            ]
        },
        {
            "x": 0,
            "y": -3,
            "z": 1,
            "elements": [
                "botania:elfglass@0"
            ]
        },
        {
            "x": -2,
            "y": 1,
            "z": -2,
            "elements": [
                "astralsorcery:blockmarbleslab@0"
            ]
        },
        {
            "x": 2,
            "y": 1,
            "z": 3,
            "elements": [
                "astralsorcery:blockmarble@5"
            ]
        },
        {
            "x": 1,
            "y": -1,
            "z": 2,
            "elements": [
                "astralsorcery:blockmarble@6"
            ]
        },
        {
            "x": -3,
            "y": 1,
            "z": -2,
            "elements": [
                "astralsorcery:blockmarbleslab@0"
            ]
        },
        {
            "x": 3,
            "y": 1,
            "z": 3,
            "elements": [
                "astralsorcery:blockmarbleslab@0"
            ]
        },
        {
            "x": 1,
            "y": -3,
            "z": 1,
            "elements": [
                "astralsorcery:blockmarble@2"
            ]
        },
        {
            "x": -3,
            "y": -5,
            "z": 4,
            "elements": [
                "astralsorcery:blockmarble@2"
            ]
        },
        {
            "x": 3,
            "y": -3,
            "z": 1,
            "elements": [
                "botania:pylon@2"
            ]
        },
        {
            "x": 3,
            "y": -5,
            "z": 4,
            "elements": [
                "astralsorcery:blockmarble@2"
            ]
        },
        {
            "x": 3,
            "y": -6,
            "z": -1,
            "elements": [
                "astralsorcery:blockmarble@1"
            ]
        },
        {
            "x": -3,
            "y": -6,
            "z": -1,
            "elements": [
                "astralsorcery:blockmarble@1"
            ]
        },
        {
            "x": 3,
            "y": 0,
            "z": -2,
            "elements": [
                "astralsorcery:blockmarble@5"
            ]
        },
        {
            "x": -1,
            "y": 2,
            "z": 3,
            "elements": [
                "astralsorcery:blockmarbleslab@0"
            ]
        },
        {
            "x": 1,
            "y": 2,
            "z": -1,
            "elements": [
                "astralsorcery:blockmarbleslab@0"
            ]
        },
        {
            "x": -1,
            "y": 0,
            "z": 2,
            "elements": [
                "astralsorcery:blockmarble@1"
            ]
        },
        {
            "x": 0,
            "y": 0,
            "z": 2,
            "elements": [
                "modulardiversity:blockmanainputhatch@0"
            ]
        },
        {
            "x": 1,
            "y": 2,
            "z": 3,
            "elements": [
                "astralsorcery:blockmarbleslab@0"
            ]
        },
        {
            "x": -1,
            "y": -2,
            "z": 1,
            "elements": [
                "astralsorcery:blockmarble@2"
            ]
        },
        {
            "x": 0,
            "y": -2,
            "z": 1,
            "elements": [
                "botania:storage@1"
            ]
        },
        {
            "x": -1,
            "y": 2,
            "z": -1,
            "elements": [
                "astralsorcery:blockmarbleslab@0"
            ]
        },
        {
            "x": 1,
            "y": 0,
            "z": 2,
            "elements": [
                "astralsorcery:blockmarble@1"
            ]
        },
        {
            "x": -3,
            "y": 0,
            "z": -2,
            "elements": [
                "astralsorcery:blockmarble@5"
            ]
        },
        {
            "x": 1,
            "y": -2,
            "z": 1,
            "elements": [
                "astralsorcery:blockmarble@2"
            ]
        },
        {
            "x": -3,
            "y": -4,
            "z": 4,
            "elements": [
                "astralsorcery:blockmarble@2"
            ]
        },
        {
            "x": -3,
            "y": -6,
            "z": 3,
            "elements": [
                "astralsorcery:blockmarble@1"
            ]
        },
        {
            "x": 3,
            "y": -4,
            "z": 4,
            "elements": [
                "astralsorcery:blockmarble@2"
            ]
        },
        {
            "x": 3,
            "y": -6,
            "z": 3,
            "elements": [
                "astralsorcery:blockmarble@1"
            ]
        },
        {
            "x": 3,
            "y": -1,
            "z": -2,
            "elements": [
                "astralsorcery:blockmarble@2"
            ]
        },
        {
            "x": 3,
            "y": 1,
            "z": -1,
            "elements": [
                "astralsorcery:blockmarbleslab@0"
            ]
        },
        {
            "x": 2,
            "y": 1,
            "z": -1,
            "elements": [
                "astralsorcery:blockmarble@5"
            ]
        },
        {
            "x": -1,
            "y": 1,
            "z": 2,
            "elements": [
                "astralsorcery:blockmarble@5"
            ]
        },
        {
            "x": 0,
            "y": 1,
            "z": 2,
            "elements": [
                "astralsorcery:blockmarble@2"
            ]
        },
        {
            "x": -1,
            "y": -1,
            "z": 1,
            "elements": [
                "astralsorcery:blockmarble@2"
            ]
        },
        {
            "x": 0,
            "y": -1,
            "z": 1,
            "elements": [
                "botania:elfglass@0"
            ]
        },
        {
            "x": 1,
            "y": 1,
            "z": 2,
            "elements": [
                "astralsorcery:blockmarble@5"
            ]
        },
        {
            "x": -3,
            "y": -1,
            "z": -2,
            "elements": [
                "astralsorcery:blockmarble@2"
            ]
        },
        {
            "x": -2,
            "y": 1,
            "z": -1,
            "elements": [
                "astralsorcery:blockmarble@5"
            ]
        },
        {
            "x": 1,
            "y": -1,
            "z": 1,
            "elements": [
                "astralsorcery:blockmarble@2"
            ]
        },
        {
            "x": -3,
            "y": 1,
            "z": -1,
            "elements": [
                "astralsorcery:blockmarbleslab@0"
            ]
        },
        {
            "x": -3,
            "y": -3,
            "z": 4,
            "elements": [
                "astralsorcery:blockmarble@2"
            ]
        },
        {
            "x": 0,
            "y": -3,
            "z": 4,
            "elements": [
                "botania:pylon@2"
            ]
        },
        {
            "x": 3,
            "y": -3,
            "z": 4,
            "elements": [
                "astralsorcery:blockmarble@2"
            ]
        },
        {
            "x": 3,
            "y": -6,
            "z": 0,
            "elements": [
                "astralsorcery:blockmarble@1"
            ]
        },
        {
            "x": 3,
            "y": -2,
            "z": -2,
            "elements": [
                "astralsorcery:blockmarble@2"
            ]
        },
        {
            "x": -3,
            "y": -6,
            "z": 0,
            "elements": [
                "astralsorcery:blockmarble@1"
            ]
        },
        {
            "x": -2,
            "y": 2,
            "z": 2,
            "elements": [
                "astralsorcery:blockmarbleslab@0"
            ]
        },
        {
            "x": -1,
            "y": 2,
            "z": 2,
            "elements": [
                "astralsorcery:blockmarbleslab@0"
            ]
        },
        {
            "x": 0,
            "y": 2,
            "z": 2,
            "elements": [
                "astralsorcery:blockmarble@1"
            ]
        },
        {
            "x": -1,
            "y": 0,
            "z": 1,
            "elements": [
                "modulardiversity:blockmanainputhatch@0"
            ]
        },
        {
            "x": 0,
            "y": 0,
            "z": 1,
            "elements": [
                "botania:storage@4"
            ]
        },
        {
            "x": 1,
            "y": 2,
            "z": 2,
            "elements": [
                "astralsorcery:blockmarbleslab@0"
            ]
        },
        {
            "x": -3,
            "y": -2,
            "z": -2,
            "elements": [
                "astralsorcery:blockmarble@2"
            ]
        },
        {
            "x": 2,
            "y": 2,
            "z": 2,
            "elements": [
                "astralsorcery:blockmarbleslab@0"
            ]
        },
        {
            "x": 1,
            "y": 0,
            "z": 1,
            "elements": [
                "modulardiversity:blockmanainputhatch@0"
            ]
        },
        {
            "x": -3,
            "y": -2,
            "z": 4,
            "elements": [
                "astralsorcery:blockmarble@2"
            ]
        },
        {
            "x": -3,
            "y": -6,
            "z": 2,
            "elements": [
                "astralsorcery:blockmarble@1"
            ]
        },
        {
            "x": 3,
            "y": -2,
            "z": 4,
            "elements": [
                "astralsorcery:blockmarble@2"
            ]
        },
        {
            "x": 3,
            "y": -6,
            "z": 2,
            "elements": [
                "astralsorcery:blockmarble@1"
            ]
        },
        {
            "x": 3,
            "y": -3,
            "z": -2,
            "elements": [
                "astralsorcery:blockmarble@2"
            ]
        },
        {
            "x": 0,
            "y": -3,
            "z": -2,
            "elements": [
                "botania:pylon@2"
            ]
        },
        {
            "x": -1,
            "y": 1,
            "z": 1,
            "elements": [
                "astralsorcery:blockmarble@2"
            ]
        },
        {
            "x": 0,
            "y": 1,
            "z": 1,
            "elements": [
                "botania:elfglass@0"
            ]
        },
        {
            "x": -3,
            "y": -3,
            "z": -2,
            "elements": [
                "astralsorcery:blockmarble@2"
            ]
        },
        {
            "x": 1,
            "y": 1,
            "z": 1,
            "elements": [
                "astralsorcery:blockmarble@2"
            ]
        },
        {
            "x": -3,
            "y": -1,
            "z": 4,
            "elements": [
                "astralsorcery:blockmarble@2"
            ]
        },
        {
            "x": 3,
            "y": -1,
            "z": 4,
            "elements": [
                "astralsorcery:blockmarble@2"
            ]
        },
        {
            "x": 3,
            "y": -4,
            "z": -2,
            "elements": [
                "astralsorcery:blockmarble@2"
            ]
        },
        {
            "x": -1,
            "y": 2,
            "z": 1,
            "elements": [
                "astralsorcery:blockmarble@1"
            ]
        },
        {
            "x": 0,
            "y": 2,
            "z": 1,
            "elements": [
                "modularmachinery:blockinputbus@0"
            ]
        },
        {
            "x": -2,
            "y": -6,
            "z": 1,
            "elements": [
                "astralsorcery:blockmarble@3"
            ]
        },
        {
            "x": -1,
            "y": -6,
            "z": 1,
            "elements": [
                "astralsorcery:blockmarble@3"
            ]
        },
        {
            "x": 0,
            "y": -6,
            "z": 1,
            "elements": [
                "astralsorcery:fluidblockliquidstarlight@0"
            ]
        },
        {
            "x": 1,
            "y": -6,
            "z": 1,
            "elements": [
                "astralsorcery:blockmarble@3"
            ]
        },
        {
            "x": 0,
            "y": -6,
            "z": 2,
            "elements": [
                "astralsorcery:blockmarble@3"
            ]
        },
        {
            "x": 2,
            "y": -6,
            "z": 1,
            "elements": [
                "astralsorcery:blockmarble@3"
            ]
        },
        {
            "x": 0,
            "y": -6,
            "z": 0,
            "elements": [
                "astralsorcery:blockmarble@3"
            ]
        },
        {
            "x": 0,
            "y": -6,
            "z": 3,
            "elements": [
                "astralsorcery:blockmarble@3"
            ]
        },
        {
            "x": 0,
            "y": -6,
            "z": -1,
            "elements": [
                "astralsorcery:blockmarble@3"
            ]
        }
    ]}